Workbook

Sheet Notes on Creative Com.
A1: We are glad to have press coverage of our studies and encourage you to share our work. We give permission for anyone to use this study’s data, analysis, and visuals as long as you:
B2: • Credit Surfshark (ideally with a link to the landing page);
B3: • Say if you made any changes to the original piece;
B4: • Don't use these materials for commercial purposes.
B5: • If you change the materials, you also need to share them under the same rules.
A6: This project is licensed under Creative Commons 3.0 and the above-mentioned conditions are taken from it. If you have any questions or concerns about sharing our work, please contact media@surfshark.com before using them.

Sheet Countries
B1: Country | C1: ISO-alpha2 Code | D1: Social media bans / heavy disruptions within the period of 2015 - present? | E1: Related w/ protests | F1: Related w/ elections | G1: Related w/ political turmoil | H1: Related w/ country’s internet law | I1: Start date | J1: End date | K1: Duration, h (ongoing cases are responsive to update date) | L1: If yes, what was the context? | M1: Scope/population? | N1: Service based restriction | O1: Facebook | P1: X (formerly Twitter) | Q1: Youtube | R1: Instagram | S1: Telegram | T1: Whatsapp | U1: Other soc. media | V1: Other VoIP apps | W1: Source
A2: Internet services restricted in the past
A3: No evidence
A4: Social media currently restricted
A5: Voice over IP (VoIP) apps currently restricted
A6: Social media and VoIP currently restricted
A7: AFRICA
A8: 1 | B8: Algeria | C8: DZ | D8: Yes | E8: TRUE | F8: FALSE | G8: FALSE | H8: FALSE | I8: 43722 | J8: 43722 | K8: 1 | L8: Internet disrupted in Algeria amid protests against military influence. | M8: Nationwide | N8: FALSE | O8: FALSE | P8: FALSE | Q8: FALSE | R8: FALSE | S8: FALSE | T8: FALSE | U8: FALSE | V8: FALSE | W8: NetBlocks
E9: FALSE | F9: FALSE | G9: TRUE | H9: FALSE | I9: 43685 | J9: 43685 | K9: 3 | L9: Algeria blocks YouTube and Google services after publication of political video. | M9: Nationwide | N9: TRUE | O9: FALSE | P9: FALSE | Q9: TRUE | R9: FALSE | S9: FALSE | T9: FALSE | U9: TRUE | V9: FALSE | W9: Netblocks
E10: TRUE | F10: FALSE | G10: FALSE | H10: FALSE | I10: 43632 | J10: 43636 | K10: 120 | L10: Algeria blocked Facebook and other social networks in an attempt tio stop students from cheating. | M10: Nationwide | N10: TRUE | O10: TRUE | P10: TRUE | Q10: FALSE | R10: TRUE | S10: TRUE | T10: TRUE | U10: TRUE | V10: TRUE | W10: Netblocks
E11: TRUE | F11: FALSE | G11: FALSE | H11: FALSE | I11: 43525 | J11: 43525 | K11: 3 | L11: Several parts of Algeria have been cut off from the internet on Friday 1 March 2019, limiting communication and media coverage of the second wave of protests against president | M11: Nationwide | N11: FALSE | O11: FALSE | P11: FALSE | Q11: FALSE | R11: FALSE | S11: FALSE | T11: FALSE | U11: FALSE | V11: FALSE | W11: Netblocks
E12: TRUE | F12: FALSE | G12: FALSE | H12: FALSE | I12: 43518 | J12: 43521 | K12: 69 | L12: The NetBlocks internet observatory has identified several regional internet disruptions across Algeria, as of Friday 22 February 2019, as the public have gone out to the streets to participate in protests. | M12: Nationwide | N12: FALSE | O12: FALSE | P12: FALSE | Q12: FALSE | R12: FALSE | S12: FALSE | T12: FALSE | U12: FALSE | V12: FALSE | W12: Netblocks
A13: 2 | B13: Angola | C13: AO | D13: No evidence | E13: FALSE | F13: FALSE | G13: FALSE | H13: FALSE | I13: N/A | J13: N/A | K13: N/A | L13: N/A | M13: N/A | N13: FALSE | O13: FALSE | P13: FALSE | Q13: FALSE | R13: FALSE | S13: FALSE | T13: FALSE | U13: FALSE | V13: FALSE
A14: 3 | B14: Benin | C14: BJ | D14: Yes | E14: FALSE | F14: TRUE | G14: FALSE | H14: FALSE | I14: 43586 | J14: 43586 | K14: 15 | L14: Internet blocked in Benin on election day. | M14: Nationwide | N14: FALSE | O14: FALSE | P14: FALSE | Q14: FALSE | R14: FALSE | S14: FALSE | T14: FALSE | U14: FALSE | V14: FALSE | W14: Netblocks
E15: TRUE | F15: FALSE | G15: FALSE | H15: FALSE | I15: 43583 | J15: 43583 | K15: 1 | L15: As Benin goes to elect its parliamentary representatives, the government has blocked social media including access to WhatsApp, Twitter, Instagram, Telegram, Facebook, LinkedIn, Tinder, and other platforms. | M15: Nationwide | N15: TRUE | O15: TRUE | P15: TRUE | Q15: FALSE | R15: TRUE | S15: TRUE | T15: TRUE | U15: TRUE | V15: FALSE | W15: Netblocks | X15: AccessNow
A16: 4 | B16: Botswana | C16: BW | D16: No evidence | E16: FALSE | F16: FALSE | G16: FALSE | H16: FALSE | I16: N/A | J16: N/A | K16: N/A | L16: N/A | M16: N/A | N16: FALSE | O16: FALSE | P16: FALSE | Q16: FALSE | R16: FALSE | S16: FALSE | T16: FALSE | U16: FALSE | V16: FALSE
A17: 5 | B17: Burkina Faso | C17: BF | D17: Social media currently restricted | E17: FALSE | F17: FALSE | G17: TRUE | H17: FALSE | I17: 44584 | J17: 44585 | K17: 35 | L17: Internet disrupted in Burkina Faso amid military uprising | M17: Nationwide | N17: FALSE | O17: FALSE | P17: FALSE | Q17: FALSE | R17: FALSE | S17: FALSE | T17: FALSE | U17: FALSE | V17: FALSE | W17: NetBlocks
E18: FALSE | F18: FALSE | G18: TRUE | H18: FALSE | I18: 44572 | J18: Ongoing | K18: =(updateDate!B$1-date(year(I18),month(I18),day(I18)+1))*24 -> 26016 | L18: On 19 January 2022, authorities admitted that they restricted access to Facebook services citing security concern. Restrictions started on 11 January. | M18: Nationwide | N18: TRUE | O18: TRUE | P18: FALSE | Q18: FALSE | R18: FALSE | S18: FALSE | T18: FALSE | U18: FALSE | V18: FALSE | W18: NetBlocks | X18: NetBlocks
E19: FALSE | F19: FALSE | G19: TRUE | H19: FALSE | I19: 44571 | J19: 44572 | K19: 15 | L19: Internet disruptions observed in Burkina Faso amid coup plot arrests. | M19: Nationwide | N19: FALSE | O19: FALSE | P19: FALSE | Q19: FALSE | R19: FALSE | S19: FALSE | T19: FALSE | U19: FALSE | V19: FALSE | W19: NetBlocks
E20: TRUE | F20: FALSE | G20: FALSE | H20: FALSE | I20: 44520 | J20: 44528 | K20: 193 | L20: Mobile internet disrupted in Burkina Faso after shooting of protesters | M20: Nationwide | N20: FALSE | O20: FALSE | P20: FALSE | Q20: FALSE | R20: FALSE | S20: FALSE | T20: FALSE | U20: FALSE | V20: FALSE | W20: NetBlocks
A21: 6 | B21: Burundi | C21: BI | D21: Yes | E21: FALSE | F21: TRUE | G21: FALSE | H21: FALSE | I21: 43971 | J21: 43972 | K21: 36 | L21: Burundi blocks social media access during presidential elections | M21: Nationwide | N21: TRUE | O21: TRUE | P21: TRUE | Q21: TRUE | R21: TRUE | S21: TRUE | T21: TRUE | U21: FALSE | V21: FALSE | W21: CPJ | X21: NetBlocks
A22: 7 | B22: Cameroon | C22: CM | D22: Yes | E22: FALSE | F22: TRUE | G22: FALSE | H22: FALSE | I22: 43394 | J22: 43394 | K22: 12 | L22: Facebook and WhatsApp restricted in Cameroon on eve of election results. | M22: Nationwide | N22: TRUE | O22: TRUE | P22: FALSE | Q22: FALSE | R22: FALSE | S22: FALSE | T22: TRUE | U22: FALSE | V22: FALSE | W22: NetBlocks
E23: TRUE | F23: FALSE | G23: FALSE | H23: FALSE | I23: 43009 | J23: 43160 | K23: 3600 | L23: The Cameroon government has again issued orders to block access to the entire internet in Anglophone regions of the country, this time in the lead up to Oct. 1, 2017, a day for planned demonstrations in those regions. | M23: Cameroon, Northwest and Southwest Regions | N23: FALSE | O23: FALSE | P23: FALSE | Q23: FALSE | R23: FALSE | S23: FALSE | T23: FALSE | U23: FALSE | V23: FALSE | W23: AccessNow | X23: AccessNow
E24: TRUE | F24: FALSE | G24: FALSE | H24: FALSE | I24: 42753 | J24: 42845 | K24: 2332 | L24: Cameroon had blocked the internet in English-speaking parts of the country. The statement also confirmed that the authorities had sent text messages direct to mobile phone subscribers, notifying them of penalties, including long jail terms, for "spreading false news" via social media. | M24: Cameroon, Northwest and Southwest Regions | N24: FALSE | O24: FALSE | P24: FALSE | Q24: FALSE | R24: FALSE | S24: FALSE | T24: FALSE | U24: FALSE | V24: FALSE | W24: Aljazeera | X24: BBC
A25: 8 | B25: Cabo Verde | C25: CV | D25: No evidence | E25: FALSE | F25: FALSE | G25: FALSE | H25: FALSE | I25: N/A | J25: N/A | K25: N/A | L25: N/A | M25: N/A | N25: FALSE | O25: FALSE | P25: FALSE | Q25: FALSE | R25: FALSE | S25: FALSE | T25: FALSE | U25: FALSE | V25: FALSE
A26: 9 | B26: The Central African Republic | C26: CF | D26: No evidence | E26: FALSE | F26: FALSE | G26: FALSE | H26: FALSE | I26: N/A | J26: N/A | K26: N/A | L26: N/A | M26: N/A | N26: FALSE | O26: FALSE | P26: FALSE | Q26: FALSE | R26: FALSE | S26: FALSE | T26: FALSE | U26: FALSE | V26: FALSE
A27: 10 | B27: Chad | C27: TD | D27: Yes | E27: FALSE | F27: FALSE | G27: TRUE | H27: FALSE | I27: 45350 | J27: 45358 | K27: 38 | L27: Metrics show a further decline in internet connectivity in #Chad following this morning's telecoms disruption; the incident comes as searches are imposed at checkpoints amid heavy gunfire in the capital following a deadly attack at the National Security Agency HQ | M27: Nationwide | N27: FALSE | O27: FALSE | P27: FALSE | Q27: FALSE | R27: FALSE | S27: FALSE | T27: FALSE | U27: FALSE | V27: FALSE | W27: Netblocks
E28: FALSE | F28: TRUE | G28: FALSE | H28: FALSE | I28: 45267 | J28: 45268 | K28: 14 | L28: Real-time network data show a nation-scale loss of internet connectivity in Chad; the incident comes amid rising political tensions just weeks ahead of a constitutional referendum | M28: Nationwide | N28: FALSE | O28: FALSE | P28: FALSE | Q28: FALSE | R28: FALSE | S28: FALSE | T28: FALSE | U28: FALSE | V28: FALSE | W28: Netblocks
E29: FALSE | F29: FALSE | G29: TRUE | H29: FALSE | I29: 44255 | J29: 44256 | K29: 32 | L29: Internet connectivity has been severely disrupted in Chad since the morning of Sunday 28 February 2021 amid reports of a deadly armed raid at the house of opposition candidate Yaya Dillo. | M29: Nationwide | N29: FALSE | O29: FALSE | P29: FALSE | Q29: FALSE | R29: FALSE | S29: FALSE | T29: FALSE | U29: FALSE | V29: FALSE | W29: NetBlocks
E30: FALSE | F30: FALSE | G30: TRUE | H30: FALSE | I30: 44034 | J30: 44116 | K30: 1961 | L30: WhatsApp messaging service blocked in Chad. | M30: Nationwide | N30: TRUE | O30: FALSE | P30: FALSE | Q30: FALSE | R30: FALSE | S30: FALSE | T30: TRUE | U30: FALSE | V30: FALSE | W30: NetBlocks
E31: TRUE | F31: FALSE | G31: FALSE | H31: FALSE | I31: 43187 | J31: 43659 | K31: 11359 | L31: Chad cut access to social media platforms, including WhatsApp, Twitter, Facebook, Instagram, and YouTube, for a staggering 472 days between 2018 and 2019. The government attempted to justify the social media blackout, stating that it was necessary for “security reasons.” However, authorities blocked access just as President Idriss Deby, who has been president of Chad since the 1990s, was pushing to stay in power until 2033. | M31: Nationwide | N31: TRUE | O31: TRUE | P31: TRUE | Q31: TRUE | R31: TRUE | S31: FALSE | T31: TRUE | U31: FALSE | V31: FALSE | W31: CNN
E32: TRUE | F32: FALSE | G32: FALSE | H32: FALSE | I32: 43125 | J32: 43126 | K32: 20 | L32: Internet access has been restored in Chad after the government ordered a shutdown in response to national protest action backed by trade unions and civil society organisations using social media. | M32: Nationwide | N32: FALSE | O32: FALSE | P32: FALSE | Q32: FALSE | R32: FALSE | S32: FALSE | T32: FALSE | U32: FALSE | V32: FALSE | W32: AccessNow | X32: ITweb
E33: FALSE | F33: TRUE | G33: FALSE | H33: FALSE | I33: 42469 | J33: 42473 | K33: 96 | L33: Chad Elections: Major internet blackout ahead of declaration | M33: Nationwide | N33: FALSE | O33: FALSE | P33: FALSE | Q33: FALSE | R33: FALSE | S33: FALSE | T33: FALSE | U33: FALSE | V33: FALSE | W33: AccessNow | X33: AfricanNews
A34: 11 | B34: Comoros | C34: KM | D34: Yes | E34: TRUE | F34: FALSE | G34: FALSE | H34: FALSE | I34: 45308 | J34: 45309 | K34: 24 | L34: Comoros disrupts internet access amid post-election protests. | M34: Nationwide | N34: FALSE | O34: FALSE | P34: FALSE | Q34: FALSE | R34: FALSE | S34: FALSE | T34: FALSE | U34: FALSE | V34: FALSE | W34: Access Now
A35: 12 | B35: Congo | C35: CG | D35: Yes | E35: FALSE | F35: TRUE | G35: FALSE | H35: FALSE | I35: 44276 | J35: 44278 | K35: 72 | L35: Republic of the Congo shut down the internet amid the presidential election. | M35: Nationwide | N35: FALSE | O35: FALSE | P35: FALSE | Q35: FALSE | R35: FALSE | S35: FALSE | T35: FALSE | U35: FALSE | V35: FALSE | W35: NetBlocks
E36: FALSE | F36: TRUE | G36: FALSE | H36: FALSE | I36: 42449 | J36: 42453 | K36: 96 | L36: Republic of the Congo shut down the internet amid the presidential election. | M36: Nationwide | N36: FALSE | O36: FALSE | P36: FALSE | Q36: FALSE | R36: FALSE | S36: FALSE | T36: FALSE | U36: FALSE | V36: FALSE | W36: Codastory | X36: Reuters
E37: FALSE | F37: FALSE | G37: TRUE | H37: FALSE | I37: 42297 | J37: 42297 | K37: 18 | L37: Government may have ordered internet shutdown in Congo-Brazzaville | M37: Nationwide | N37: FALSE | O37: FALSE | P37: FALSE | Q37: FALSE | R37: FALSE | S37: FALSE | T37: FALSE | U37: FALSE | V37: FALSE | W37: RSF | X37: AcessNow
A38: 13 | B38: Ivory Coast | C38: CI | D38: No evidence | E38: FALSE | F38: FALSE | G38: FALSE | H38: FALSE | I38: N/A | J38: N/A | K38: N/A | L38: N/A | M38: N/A | N38: FALSE | O38: FALSE | P38: FALSE | Q38: FALSE | R38: FALSE | S38: FALSE | T38: FALSE | U38: FALSE | V38: FALSE
A39: 14 | B39: Congo DR | C39: CD | D39: Yes | E39: FALSE | F39: TRUE | G39: FALSE | H39: FALSE | I39: 43465 | J39: 43465 | K39: 480 | L39: The NetBlocks internet shutdown observatory has collected technical evidence of multiple internet disruptions in the Democratic Republic of Congo as of Monday 31 December 2018 amid contested general elections. | M39: Nationwide | N39: FALSE | O39: FALSE | P39: FALSE | Q39: FALSE | R39: FALSE | S39: FALSE | T39: FALSE | U39: FALSE | V39: FALSE | W39: NetBlocks | X39: Aljazeera
E40: TRUE | F40: FALSE | G40: FALSE | H40: FALSE | I40: 43156 | J40: 43156 | K40: 10 | L40: at around 9 A.M. on February 25, 2018, internet and SMS services were blocked–this time for about 10 hours–as more protests occurred across the country, | M40: Nationwide | N40: FALSE | O40: FALSE | P40: FALSE | Q40: FALSE | R40: FALSE | S40: FALSE | T40: FALSE | U40: FALSE | V40: FALSE | W40: CPJ
...

Sheet internetshutdowns.in cases
B1: Country | C1: ISO-alpha2 Code | D1: Social media bans / heavy disruptions within the period of 2015 - present? | E1: Related w/ protests | F1: Related w/ elections | G1: Related w/ political turmoil | H1: Related w/ country’s internet law | I1: Start date | J1: End date | K1: Duration, h (Updates everyday) | L1: If yes, what was the context? | M1: Scope/population? | N1: Service based restriction | O1: Facebook | P1: Twitter | Q1: Youtube | R1: Instagram | S1: Telegram | T1: Whatsapp | U1: Other soc. media | V1: Other VoIP apps | W1: Source | Z1: Notes
A2: Social media blocked in the past
A3: No evidence
A4: Social media currently blocked
A5: Voice over IP (VoIP) apps currently blocked
A6: Social media and VoIP currently restricted
A7: ASIA

Sheet Other cases
A1: Country | B1: Affected service | C1: Date | D1: Description | E1: Sources
A2: Russia | B2: Navalny app | C2: 44456 | D2: Opposition election voting app Navalny removed from Apple App Store and Google Play Store in Russia. Removed from Apple App Store and Google Play Store on 9/17/2021. Reinstated by Google on 10/09/2021. Reinstated on Apple App Store on 4/5/2022. | E2: NetBlocks | F2: Apple Censorship | G2: https://russianfreepress.com/2021/10/09/google-restored-the-navalny-app-videos-and-smart-voting-documents/
A3: Slovakia | B3: Twitch | C3: 44371 | D3: One Slovakian ISP (O2) banned Twitch as a result of a streamer playing poker live. Other ISPs followed or were due to follow. Slovakia has strict laws surrounding gambling, as the streamer was "said to have broken laws around the operation of promotion of gambling by playing internet poker." | E3: Dexerto.com | F3: Guided.news
A4: U.K. | B4: Public Wi-Fi in London Underground | C4: 43572 | D4: UK police shut off Wi-Fi in London Tube stations to deter climate protestors. | E4: Independent
A5: Venezuela | B5: Wikipedia | C5: 43477 | D5: Wikipedia blocked by the largest telecommunications provider CANTV, following a bitter edit war where editors put forward conflicting views. | E5: NetBlocks | F5: VEsinFiltro | G5: OONI
A6: Spain | B6: Catalonian websites | C6: September - October 2017 | D6: During the days before the 2017 Catalan independence referendum, the Civil Guard closed the official website of the referendum. It also closed or blocked multiple alternative domains, official and non official. On 20 September the Civil Guard entered the headquarters of the Fundació puntCat, which administers the top-level domain .cat, and arrested the director of IT, Pep Masoliver. By 27 September, more than 140 websites related to the referendum were blocked. On 11 October, the official website of the Assemblea Nacional Catalana organization, assemblea.cat, was blocked. | E6: Wikipedia | F6: VentureBeat
A7: Philippines | B7: Mobile internet | C7: 2015 - 2018 | D7: The first known mobile network shutdown in the Philippines was during the Papal visit in 2015. Since then, signal jamming has been frequently used as a go-to security mechanism for large events, citing public safety as the main concern. | E7: Access Now | F7: Freedom House | G7: Inquirer.net
A8: Guyana | B8: VoIP services | C8: 12/2/2008 - ongoing | D8: Skype (and other VoIP services?) blocked nationwide. | E8: NordVPN blog | F8: VPN Overview | G8: freegyvoip.com
A9: Lebanon | B9: Internet service | C9: 44576 | D9: Loss of internet service in parts of Beirut, Lebanon, following an escalating pattern of destabilization of infrastructure as the country’s energy crisis deepens. | E9: NetBlocks
A10: Pakistan | B10: Slate Magazine website | C10: 43294 | D10: Slate Magazine blocked in Pakistan amid deteriorating conditions for online media freedom. | E10: https://netblocks.org/reports/slate-magazine-blocked-in-pakistan-qr8Vary5
A11: Pakistan | B11: Political party website | C11: 43254 | D11: Evidence of blocking of a political party website, operated by the Awami Workers Party, in the run up to general elections scheduled on the 25th of July 2018. | E11: https://netblocks.org/reports/study-reveals-extent-of-awami-workers-political-party-website-block-in-pakistan-zgBLrk84
A12: Venezuela | B12: Humanitarian aid volunteer web platform | C12: 43512 | D12: Volunteer registration web platform for Venezuela’s Coalition for Aid and Freedom blocked as members took to the streets, | E12: https://netblocks.org/reports/venezuela-humanitarian-aid-platform-blocked-GnAgJk8p
A13: Venezuela | B13: Wikipedia | C13: 43477 | D13: Wikipedia blocked in Venezuela as internet controls tighten. | E13: https://netblocks.org/reports/wikipedia-blocked-in-venezuela-as-internet-controls-tighten-XaAwR08M
A14: Russia | B14: Internet service | C14: 44265 | D14: Internet disrupted in Russia as regulator imposed new measures. | E14: https://netblocks.org/reports/internet-disrupted-in-russia-as-regulator-imposes-new-measures-l8WxaQAO
A15: Algeria | B15: Internet service | C15: 44087 | D15: Internet connectivity significantly disrupted for one hour during school exams. | E15: https://netblocks.org/reports/social-media-restricted-and-internet-cut-during-algeria-school-exams-xAGolxAz
A16: Algeria | B16: Facebook, Twitter, other social media | C16: 42541 | D16: Facebook, Twitter and other social networks blocked in an attempt to stop students from cheating during exams. | E16: The Independent
A17: Global | B17: Facebook, WhatsApp, Instagram, Messenger | C17: 43569 | D17: Several Facebook, WhatsApp, Instagram and Messenger servers showed signs of partial global outage, with availability falling to around 40% globally. | E17: https://netblocks.org/reports/facebook-whatsapp-instagram-messenger-down-globally-WJBZvWB6
A18: Iran | B18: Internet service | C18: 44020 | D18: Power-cut and outage in Armenia resulted in a knock-on loss of international connectivity in Iran. | E18: https://netblocks.org/reports/internet-in-iran-disrupted-knock-on-effect-of-power-cut-in-armenia-RyjPQ1Ag
A19: Egypt | B19: 34k domains | C19: 43570 | D19: Internet providers in Egypt blocked access to an estimated 34,000 internet domains in an apparent bid to stamp out an opposition campaign. Websites included prominent technology startups, self-help websites, celebrity homepages, dozens of Open Source technology projects, as well as Bahá’í, Jewish and Islamic faith group websites and NGOs. | E19: https://netblocks.org/reports/egypt-filters-34000-domains-in-bid-to-block-opposition-campaign-platform-7eA1blBp
A20: Egypt | B20: bit.ly | C20: 43573 | D20: Several Internet providers in Egypt restricted access to the bit.ly URL shortener service, breaking an estimated 37.5 billion web links. Reason for the 12-hour restrictions unknown. | E20: https://netblocks.org/reports/bitly-link-shortener-blocked-in-egypt-018lRLBa
... A39: Russia | B39: Amnesty International Eurasian website | C39: 44632 | D39: The Eurasia website of rights organization Amnesty International, which hosts a petition to end Russia's aggression against Ukraine, has been restricted in Russia. The measure follows social media and news site restrictions. | E39: NetBlocks
A40: Pakistan | B40: Wikipedia | C40: 02-03-2023 - 02-06-2023 | D40: Wikipedia restricted on multiple internet providers from Friday, February 3rd 2023 to Monday, February 6th 2023. The incident had come days after authorities threatened to ban the popular resource over the presence of “sacrilegious” content. Access was restored after an intervention by the Prime Minister. | E40: NetBlocks
A41: Italy | B41: ChatGPT | C41: 4/1/2023 - ongoing | D41: ChatGPT banned in Italy over privacy concerns, making Italy the first Western country to block the advanced chatbot. | E41: BBC

Sheet 2024
A1: Summary of 2024. Below the summary, there is a list of all the 2024 cases
A2: ISO-2 | B2: Countries restricting the internet in 2024 | C2: Newly imposed restrictions in 2024 Internet disruptions | D2: Affected people (if there were fer restrictions imposed in a country, biggest population sample is used); Data from UN, World Population Prospects 2022 | E2: Related w/ protests | F2: Related w/ elections | G2: Related w/ political turmoil | H2: Related w/ country’s internet law | I2: Soc media | J2: Local internet | K2: Nationwide internet | L2: Registered cases since 2015 | M2: Currently blocking | N2: Region
A3: BF | B3: Burkina Faso | C3: 0 | D3: 22959516 | E3: 0 | F3: 0 | G3: 0 | H3: 0 | I3: 0 | J3: 0 | K3: 0 | L3: 4 | M3: 1 | N3: Africa
A4: TD | B4: Chad | C4: 1 | D4: 17997367 | E4: 0 | F4: 0 | G4: 1 | H4: 0 | I4: 0 | J4: 0 | K4: 1 | L4: 7 | M4: 0 | N4: Africa
A5: KM | B5: Comoros | C5: 1 | D5: 844302 | E5: 1 | F5: 0 | G5: 0 | H5: 0 | I5: 0 | J5: 0 | K5: 1 | L5: 1 | M5: 0 | N5: Africa
A6: ER | B6: Eritrea | C6: 0 | D6: 3715522 | E6: 0 | F6: 0 | G6: 0 | H6: 0 | I6: 0 | J6: 0 | K6: 0 | L6: 2 | M6: 1 | N6: Africa
A7: ET | B7: Ethiopia | C7: 0 | D7: 124937259 | E7: 0 | F7: 0 | G7: 0 | H7: 0 | I7: 0 | J7: 0 | K7: 0 | L7: 12 | M7: 2 | N7: Africa
A8: GN | B8: Guinea | C8: 0 | D8: 14023588 | E8: 0 | F8: 0 | G8: 0 | H8: 0 | I8: 0 | J8: 0 | K8: 0 | L8: 5 | M8: 1 | N8: Africa
A9: KE | B9: Kenya | C9: 2 | D9: 54555095 | E9: 1 | F9: 0 | G9: 1 | H9: 0 | I9: 1 | J9: 0 | K9: 1 | L9: 2 | M9: 1 | N9: Africa
A10: MU | B10: Mauritius | C10: 1 | D10: 1299804 | E10: 0 | F10: 1 | G10: 0 | H10: 0 | I10: 0 | J10: 0 | K10: 1 | L10: 1 | M10: 0 | N10: Africa
A11: MZ | B11: Mozambique | C11: 8 | D11: 33420619 | E11: 8 | F11: 0 | G11: 0 | H11: 0 | I11: 2 | J11: 0 | K11: 6 | L11: 8 | M11: 2 | N11: Africa
A12: NG | B12: Nigeria | C12: 1 | D12: 221153992 | E12: 1 | F12: 0 | G12: 0 | H12: 0 | I12: 0 | J12: 0 | K12: 1 | L12: 2 | M12: 0 | N12: Africa
A13: SN | B13: Senegal | C13: 2 | D13: 17536231 | E13: 1 | F13: 1 | G13: 0 | H13: 0 | I13: 0 | J13: 1 | K13: 1 | L13: 8 | M13: 1 | N13: Africa
A14: SO | B14: Somalia | C14: 0 | D14: 17865030 | E14: 0 | F14: 0 | G14: 0 | H14: 0 | I14: 0 | J14: 0 | K14: 0 | L14: 4 | M14: 1 | N14: Africa
... A40: VE | B40: Venezuela | C40: 0 | D40: 28555733 | E40: 0 | F40: 0 | G40: 0 | H40: 0 | I40: 0 | J40: 0 | K40: 0 | L40: 36 | M40: 0 | N40: South America
A43: List of all restrictions in 2024
A44: Iso-2 array | B44: Start date | C44: End date | D44: Duration (until the end of 2022), h | E44: Related w/ protests | F44: Related w/ elections | G44: Related w/ political turmoil | H44: Related w/ country’s internet law | I44: Scope/ population | J44: Region | K44: Population; Data from UN, World Population Prospects 2022 | L44: Facebook | M44: Twitter | N44: Youtube | O44: Instagram | P44: Telegram | Q44: Whatsapp | R44: Other soc. media | S44: Other VoIP apps | T44: Cases that started and ended in chosen period | U44: Cases that started in chosen period and are still ongoing | V44: Cases that started earlier but ended in chosen period | W44: Cases that started earlier and are still ongoing | X44: Cases that started in this period
A45: AZ | B45: 45188 | D45: 11232 | E45: FALSE | F45: FALSE | G45: TRUE | H45: FALSE | I45: Nagorno-Karabakh | J45: Asia | K45: 120000 | L45: FALSE | M45: FALSE | N45: FALSE | O45: FALSE | P45: FALSE | Q45: FALSE | R45: FALSE | S45: FALSE | W45: Y
A46: BD | B46: 45509 | C46: 45509 | D46: 4 | E46: TRUE | F46: FALSE | G46: FALSE | H46: FALSE | I46: Nationwide | J46: Asia | K46: 172075151 | L46: FALSE | M46: FALSE | N46: FALSE | O46: FALSE | P46: FALSE | Q46: FALSE | R46: FALSE | S46: FALSE | T46: Y | X46: Y
A47: BD | B47: 45506 | D47: 3600 | E47: TRUE | F47: FALSE | G47: FALSE | H47: FALSE | I47: Nationwide | J47: Asia | K47: 172075151 | L47: TRUE | M47: FALSE | N47: FALSE | O47: FALSE | P47: FALSE | Q47: TRUE | R47: FALSE | S47: FALSE | U47: Y | X47: Y
A48: BD | B48: 45491 | C48: 45501 | D48: 264 | E48: TRUE | F48: FALSE | G48: FALSE | H48: FALSE | I48: Nationwide | J48: Asia | K48: 172075151 | L48: FALSE | M48: FALSE | N48: FALSE | O48: FALSE | P48: FALSE | Q48: FALSE | R48: FALSE | S48: FALSE | T48: Y | X48: Y
A49: BD | B49: 45489 | C49: 45504 | D49: 360 | E49: TRUE | F49: FALSE | G49: FALSE | H49: FALSE | I49: Nationwide | J49: Asia | K49: 172075151 | L49: TRUE | M49: FALSE | N49: FALSE | O49: FALSE | P49: FALSE | Q49: FALSE | R49: FALSE | S49: FALSE | T49: Y | X49: Y
A50: BF | B50: 44572 | D50: 26016 | E50: FALSE | F50: FALSE | G50: TRUE | H50: FALSE | I50: Nationwide | J50: Africa | K50: 22959516 | L50: TRUE | M50: FALSE | N50: FALSE | O50: FALSE | P50: FALSE | Q50: FALSE | R50: FALSE | S50: FALSE | W50: Y
A51: BR | B51: 45535 | C51: 45573 | D51: 912 | E51: FALSE | F51: FALSE | G51: FALSE | H51: TRUE | I51: Nationwide | J51: South America | K51: 215802222 | L51: FALSE | M51: TRUE | N51: FALSE | O51: FALSE | P51: FALSE | Q51: FALSE | R51: FALSE | S51: FALSE | T51: Y | X51: Y
A52: ET | B52: 44967 | D52: 16536 | E52: TRUE | F52: FALSE | G52: FALSE | H52: FALSE | I52: Nationwide | J52: Africa | K52: 124937259 | L52: FALSE | M52: FALSE | N52: TRUE | O52: FALSE | P52: FALSE | Q52: FALSE | R52: FALSE | S52: FALSE | W52: Y
A53: ET | B53: 44966 | D53: 16560 | E53: TRUE | F53: FALSE | G53: FALSE | H53: FALSE | I53: Nationwide | J53: Africa | K53: 124937259 | L53: TRUE | M53: FALSE | N53: FALSE | O53: FALSE | P53: TRUE | Q53: FALSE | R53: TRUE | S53: FALSE | W53: Y
A54: GN | B54: 45254 | D54: 9648 | E54: FALSE | F54: FALSE | G54: TRUE | H54: FALSE | I54: Nationwide | J54: Africa | K54: 14023588 | L54: TRUE | M54: FALSE | N54: FALSE | O54: FALSE | P54: TRUE | Q54: TRUE | R54: FALSE | S54: FALSE | W54: Y
A55: IN | B55: 45640 | C55: 45641 | D55: 24 | E55: TRUE | F55: FALSE | G55: FALSE | H55: FALSE | I55: Haryana | J55: Asia | K55: 30870000 | L55: FALSE | M55: FALSE | N55: FALSE | O55: FALSE | P55: FALSE | Q55: FALSE | R55: FALSE | S55: FALSE | T55: Y | X55: Y
A56: IN | B56: 45632 | C56: 45633 | D56: 24 | E56: TRUE | F56: FALSE | G56: FALSE | H56: FALSE | I56: Haryana | J56: Asia | K56: 30870000 | L56: FALSE | M56: FALSE | N56: FALSE | O56: FALSE | P56: FALSE | Q56: FALSE | R56: FALSE | S56: FALSE | T56: Y | X56: Y
A57: IN | B57: 45620 | C57: 45621 | D57: 24 | E57: FALSE | F57: FALSE | G57: TRUE | H57: FALSE | I57: Sambhal | J57: Asia | K57: 312000 | L57: FALSE | M57: FALSE | N57: FALSE | O57: FALSE | P57: FALSE | Q57: FALSE | R57: FALSE | S57: FALSE | T57: Y | X57: Y
A58: IN | B58: 45612 | C58: 45612 | D58: 24 | E58: FALSE | F58: FALSE | G58: TRUE | H58: FALSE | I58: Murshidabad | J58: Asia | K58: 44019 | L58: FALSE | M58: FALSE | N58: FALSE | O58: FALSE | P58: FALSE | Q58: FALSE | R58: FALSE | S58: FALSE | T58: Y | X58: Y
A59: IN | B59: 45612 | C59: 45633 | D59: 504 | E59: FALSE | F59: FALSE | G59: TRUE | H59: FALSE | I59: Manipur | J59: Asia | K59: 3436948 | L59: FALSE | M59: FALSE | N59: FALSE | O59: FALSE | P59: FALSE | Q59: FALSE | R59: FALSE | S59: FALSE | T59: Y | X59: Y
A60: IN | B60: 45608 | C60: 45495 | D60: 24 | E60: FALSE | F60: FALSE | G60: TRUE | H60: FALSE | I60: Dudyala, Kodangal, and Bonraspet | J60: Asia | K60: 24010 | L60: FALSE | M60: FALSE | N60: FALSE | O60: FALSE | P60: FALSE | Q60: FALSE | R60: FALSE | S60: FALSE | T60: Y | X60: Y
A61: IN | B61: 45580 | C61: 45583 | D61: 72 | E61: TRUE | F61: FALSE | G61: FALSE | H61: FALSE | I61: North Tripura | J61: Asia | K61: 693947 | L61: FALSE | M61: FALSE | N61: FALSE | O61: FALSE | P61: FALSE | Q61: FALSE | R61: FALSE | S61: FALSE | T61: Y | X61: Y
A62: IN | B62: 45579 | C62: 45579 | D62: 24 | E62: TRUE | F62: FALSE | G62: FALSE | H62: FALSE | I62: Bahraich | J62: Asia | K62: 3487731 | L62: FALSE | M62: FALSE | N62: FALSE | O62: FALSE | P62: FALSE | Q62: FALSE | R62: FALSE | S62: FALSE | T62: Y | X62: Y
A63: IN | B63: 45563 | C63: 45565 | D63: 48 | E63: TRUE | F63: FALSE | G63: FALSE | H63: FALSE | I63: Bhadrak | J63: Asia | K63: 1506337 | L63: FALSE | M63: FALSE | N63: FALSE | O63: FALSE | P63: FALSE | Q63: FALSE | R63: FALSE | S63: FALSE | T63: Y | X63: Y
A64: IN | B64: 45556 | C64: 45557 | D64: 6 | E64: FALSE | F64: FALSE | G64: TRUE | H64: FALSE | I64: Jharkhand | J64: Asia | K64: 32988134 | L64: FALSE | M64: FALSE | N64: FALSE | O64: FALSE | P64: FALSE | Q64: FALSE | R64: FALSE | S64: FALSE | T64: Y | X64: Y
A65: IN | B65: 45540 | C65: 45541 | D65: 24 | E65: FALSE | F65: FALSE | G65: TRUE | H65: FALSE | I65: Jainoor, Asifabad | J65: Asia | K65: 29401 | L65: FALSE | M65: FALSE | N65: FALSE | O65: FALSE | P65: FALSE | Q65: FALSE | R65: FALSE | S65: FALSE | T65: Y | X65: Y
A66: IN | B66: 45545 | C66: 45550 | D66: 120 | E66: TRUE | F66: FALSE | G66: FALSE | H66: FALSE | I66: Manipur | J66: Asia | K66: 3436948 | L66: FALSE | M66: FALSE | N66: FALSE | O66: FALSE | P66: FALSE | Q66: FALSE | R66: FALSE | S66: FALSE | T66: Y | X66: Y
... A71: IN | B71: 45461 | C71: 45465 | D71: 96 | E71: FALSE | F71: FALSE | G71: TRUE | H71: FALSE | I71: Balasore | J71: Asia | K71: 2680000 | L71: FALSE | M71: FALSE | N71: FALSE | O71: FALSE | P71: FALSE | Q71: FALSE | R71: FALSE | S71: FALSE | T71: Y | X71: Y
...

Sheet 2024 vs. 2023
A1: Summary of 2024 and 2023
A2: ISO-2 | B2: Countries restricting the internet in 2024 | C2: Newly imposed restrictions in 2024 Internet disruptions | D2: Affected people (if there were fer restrictions imposed in a country, biggest population sample is used); Data from UN, World Population Prospects 2022 | E2: Related w/ protests | F2: Related w/ elections | G2: Related w/ political turmoil | H2: Related w/ country’s internet law | I2: Soc media | J2: Local internet | K2: Nationwide internet | L2: Registered cases since 2015 | M2: Currently blocking | N2: Region
A3: BF | B3: Burkina Faso | C3: 0 | D3: 22959516 | E3: 0 | F3: 0 | G3: 0 | H3: 0 | I3: 0 | J3: 0 | K3: 0 | L3: 4 | M3: 1 | N3: Africa
A4: TD | B4: Chad | C4: 1 | D4: 17997367 | E4: 0 | F4: 0 | G4: 1 | H4: 0 | I4: 0 | J4: 0 | K4: 1 | L4: 7 | M4: 0 | N4: Africa
A5: KM | B5: Comoros | C5: 1 | D5: 844302 | E5: 1 | F5: 0 | G5: 0 | H5: 0 | I5: 0 | J5: 0 | K5: 1 | L5: 1 | M5: 0 | N5: Africa
A6: ER | B6: Eritrea | C6: 0 | D6: 3715522 | E6: 0 | F6: 0 | G6: 0 | H6: 0 | I6: 0 | J6: 0 | K6: 0 | L6: 2 | M6: 1 | N6: Africa
A7: ET | B7: Ethiopia | C7: 0 | D7: 124937259 | E7: 0 | F7: 0 | G7: 0 | H7: 0 | I7: 0 | J7: 0 | K7: 0 | L7: 12 | M7: 2 | N7: Africa
A8: GN | B8: Guinea | C8: 0 | D8: 14023588 | E8: 0 | F8: 0 | G8: 0 | H8: 0 | I8: 0 | J8: 0 | K8: 0 | L8: 5 | M8: 1 | N8: Africa
A9: KE | B9: Kenya | C9: 2 | D9: 54555095 | E9: 1 | F9: 0 | G9: 1 | H9: 0 | I9: 1 | J9: 0 | K9: 1 | L9: 2 | M9: 1 | N9: Africa
A10: MU | B10: Mauritius | C10: 1 | D10: 1299804 | E10: 0 | F10: 1 | G10: 0 | H10: 0 | I10: 0 | J10: 0 | K10: 1 | L10: 1 | M10: 0 | N10: Africa
A11: MZ | B11: Mozambique | C11: 8 | D11: 33420619 | E11: 8 | F11: 0 | G11: 0 | H11: 0 | I11: 2 | J11: 0 | K11: 6 | L11: 8 | M11: 2 | N11: Africa
A12: NG | B12: Nigeria | C12: 1 | D12: 221153992 | E12: 1 | F12: 0 | G12: 0 | H12: 0 | I12: 0 | J12: 0 | K12: 1 | L12: 2 | M12: 0 | N12: Africa
A13: SN | B13: Senegal | C13: 2 | D13: 17536231 | E13: 1 | F13: 1 | G13: 0 | H13: 0 | I13: 0 | J13: 1 | K13: 1 | L13: 8 | M13: 1 | N13: Africa
A14: SO | B14: Somalia | C14: 0 | D14: 17865030 | E14: 0 | F14: 0 | G14: 0 | H14: 0 | I14: 0 | J14: 0 | K14: 0 | L14: 4 | M14: 1 | N14: Africa
... A40: VE | B40: Venezuela | C40: 0 | D40: 28555733 | E40: 0 | F40: 0 | G40: 0 | H40: 0 | I40: 0 | J40: 0 | K40: 0 | L40: 36 | M40: 0 | N40: South America
A45: 2023
B46: Countries restricting the internet in 2023'H1 | C46: Newly imposed restrictions in 2023'H1 Internet disruptions | D46: Affected people (if there were fer restrictions imposed in a country, biggest population sample is used); Data from UN, World Population Prospects 2022 | E46: Related w/ protests | F46: Related w/ elections | G46: Related w/ political turmoil | H46: Related w/ country’s internet law | I46: Soc media | J46: Local internet | K46: Nationwide internet | L46: Registered cases since 2015 | M46: Currently blocking | N46: Region
A47: BF | B47: Burkina Faso | C47: 0 | D47: 22959516 | E47: 0 | F47: 0 | G47: 0 | H47: 0 | I47: 0 | J47: 0 | K47: 0 | L47: 4 | M47: 1 | N47: Africa
A48: ER | B48: Eritrea | C48: 0 | D48: 3715522 | E48: 0 | F48: 0 | G48: 0 | H48: 0 | I48: 0 | J48: 0 | K48: 0 | L48: 2 | M48: 1 | N48: Africa
A49: ET | B49: Ethiopia | C49: 2 | D49: 124937259 | E49: 2 | F49: 0 | G49: 0 | H49: 0 | I49: 2 | J49: 0 | K49: 0 | L49: 12 | M49: 3 | N49: Africa
A50: GN | B50: Guinea | C50: 1 | D50: 14023588 | E50: 1 | F50: 0 | G50: 0 | H50: 0 | I50: 1 | J50: 0 | K50: 0 | L50: 4 | M50: 1 | N50: Africa
A51: MR | B51: Mauritania | C51: 2 | D51: 4798604 | E51: 2 | F51: 0 | G51: 0 | H51: 0 | I51: 0 | J51: 0 | K51: 2 | L51: 3 | M51: 0 | N51: Africa
A52: SN | B52: Senegal | C52: 2 | D52: 17536231 | E52: 0 | F52: 0 | G52: 2 | H52: 0 | I52: 1 | J52: 0 | K52: 1 | L52: 3 | M52: 0 | N52: Africa
A53: SD | B53: Sudan | C53: 1 | D53: 47486909 | E53: 0 | F53: 0 | G53: 1 | H53: 0 | I53: 0 | J53: 0 | K53: 1 | L53: 12 | M53: 1 | N53: Africa
A54: TZ | B54: Tanzania | C54: 1 | D54: 66455898 | E54: 0 | F54: 0 | G54: 1 | H54: 0 | I54: 1 | J54: 0 | K54: 0 | L54: 2 | M54: 0 | N54: Africa
A55: CN | B55: China | C55: 0 | D55: 1425849288 | E55: 0 | F55: 0 | G55: 0 | H55: 0 | I55: 0 | J55: 0 | K55: 0 | L55: 4 | M55: 4 | N55: Asia
A56: KP | B56: North Korea | C56: 0 | D56: 26116716 | E56: 0 | F56: 0 | G56: 0 | H56: 0 | I56: 0 | J56: 0 | K56: 0 | L56: 3 | M56: 3 | N56: Asia
A57: IN | B57: India | C57: 9 | D57: 1422026528 | E57: 7 | F57: 0 | G57: 2 | H57: 0 | I57: 1 | J57: 8 | K57: 0 | L57: 111 | M57: 3 | N57: Asia
A58: IR | B58: Iran | C58: 14 | D58: 88844498 | E58: 14 | F58: 0 | G58: 0 | H58: 0 | I58: 0 | J58: 14 | K58: 0 | L58: 41 | M58: 5 | N58: Asia
... A75: J&K | B75: Jammu and Kashmir | C75: 2 | D75: 13606320 | E75: 0 | F75: 0 | G75: 2 | H75: 0 | I75: 0 | J75: 2 | K75: 0 | L75: 326 | M75: 0 | N75: Asia

Sheet 2023
A1: Summary of 2023. Below the summary, there is a list of all the 2023 cases
A2: ISO-2 | B2: Countries restricting the internet in 2023 | C2: Newly imposed restrictions in 2023 Internet disruptions | D2: Affected people (if there were fer restrictions imposed in a country, biggest population sample is used); Data from UN, World Population Prospects 2022 | E2: Related w/ protests | F2: Related w/ elections | G2: Related w/ political turmoil | H2: Related w/ country’s internet law | I2: Soc media | J2: Local internet | K2: Nationwide internet | L2: Registered cases since 2015 | M2: Currently blocking | N2: Region
A3: BF | B3: Burkina Faso | C3: 0 | D3: 22959516 | E3: 0 | F3: 0 | G3: 0 | H3: 0 | I3: 0 | J3: 0 | K3: 0 | L3: 4 | M3: 1 | N3: Africa
A4: TD | B4: Chad | C4: 1 | D4: 17997367 | E4: 0 | F4: 1 | G4: 0 | H4: 0 | I4: 0 | J4: 0 | K4: 1 | L4: 6 | M4: 0 | N4: Africa
A5: ER | B5: Eritrea | C5: 0 | D5: 3715522 | E5: 0 | F5: 0 | G5: 0 | H5: 0 | I5: 0 | J5: 0 | K5: 0 | L5: 2 | M5: 1 | N5: Africa
A6: ET | B6: Ethiopia | C6: 2 | D6: 124937259 | E6: 2 | F6: 0 | G6: 0 | H6: 0 | I6: 2 | J6: 0 | K6: 0 | L6: 12 | M6: 2 | N6: Africa
A7: GA | B7: Gabon | C7: 1 | D7: 2412778 | E7: 0 | F7: 1 | G7: 0 | H7: 0 | I7: 0 | J7: 0 | K7: 1 | L7: 3 | M7: 0 | N7: Africa
A8: GN | B8: Guinea | C8: 2 | D8: 14023588 | E8: 1 | F8: 0 | G8: 1 | H8: 0 | I8: 2 | J8: 0 | K8: 0 | L8: 5 | M8: 2 | N8: Africa
A9: MR | B9: Mauritania | C9: 2 | D9: 4798604 | E9: 2 | F9: 0 | G9: 0 | H9: 0 | I9: 0 | J9: 0 | K9: 2 | L9: 3 | M9: 0 | N9: Africa
A10: SN | B10: Senegal | C10: 5 | D10: 17536231 | E10: 3 | F10: 0 | G10: 2 | H10: 0 | I10: 3 | J10: 0 | K10: 2 | L10: 6 | M10: 1 | N10: Africa
A11: SO | B11: Somalia | C11: 1 | D11: 17865030 | E11: 0 | F11: 0 | G11: 1 | H11: 0 | I11: 1 | J11: 0 | K11: 0 | L11: 4 | M11: 1 | N11: Africa
A12: SD | B12: Sudan | C12: 1 | D12: 47486909 | E12: 0 | F12: 0 | G12: 1 | H12: 0 | I12: 0 | J12: 0 | K12: 1 | L12: 12 | M12: 0 | N12: Africa
A13: TZ | B13: Tanzania | C13: 1 | D13: 66455898 | E13: 0 | F13: 0 | G13: 1 | H13: 0 | I13: 1 | J13: 0 | K13: 0 | L13: 2 | M13: 0 | N13: Africa
A14: ZW | B14: Zimbabwe | C14: 1 | D14: 16488132 | E14: 0 | F14: 1 | G14: 0 | H14: 0 | I14: 1 | J14: 0 | K14: 0 | L14: 7 | M14: 0 | N14: Africa
... A38: VE | B38: Venezuela | C38: 1 | D38: 28555733 | E38: 0 | F38: 1 | G38: 0 | H38: 0 | I38: 0 | J38: 0 | K38: 1 | L38: 35 | M38: 0 | N38: South America
A43: List of all restrictions in 2023
A44: Iso-2 array | B44: Start date | C44: End date | D44: Duration (until the end of 2022), h | E44: Related w/ protests | F44: Related w/ elections | G44: Related w/ political turmoil | H44: Related w/ country’s internet law | I44: Scope/ population | J44: Region | K44: Population; Data from UN, World Population Prospects 2022 | L44: Facebook | M44: Twitter | N44: Youtube | O44: Instagram | P44: Telegram | Q44: Whatsapp | R44: Other soc. media | S44: Other VoIP apps | T44: Service based restriction | U44: Cases that started and ended in chosen period | V44: Cases that started in chosen period and are still ongoing | W44: Cases that started earlier but ended in chosen period | X44: Cases that started earlier and are still ongoing | Y44: Cases that started in this period
A45: BF | B45: 44572 | D45: 17256 | E45: FALSE | F45: FALSE | G45: TRUE | H45: FALSE | I45: Nationwide | J45: Africa | K45: 22959516 | L45: TRUE | M45: FALSE | N45: FALSE | O45: FALSE | P45: FALSE | Q45: FALSE | R45: FALSE | S45: FALSE | T45: TRUE | X45: Y
A46: TD | B46: 45267 | C46: 45268 | D46: 14 | E46: FALSE | F46: TRUE | G46: FALSE | H46: FALSE | I46: Nationwide | J46: Africa | K46: 17997367 | L46: FALSE | M46: FALSE | N46: FALSE | O46: FALSE | P46: FALSE | Q46: FALSE | R46: FALSE | S46: FALSE | T46: FALSE | U46: Y | Y46: Y
A47: ER | B47: 40544 | D47: 113928 | E47: FALSE | F47: FALSE | G47: TRUE | H47: FALSE | I47: Nationwide | J47: Africa | K47: 3715522 | L47: FALSE | M47: FALSE | N47: TRUE | O47: FALSE | P47: FALSE | Q47: FALSE | R47: FALSE | S47: FALSE | T47: TRUE | X47: Y
A48: ET | B48: 44967 | D48: 7776 | E48: TRUE | F48: FALSE | G48: FALSE | H48: FALSE | I48: Nationwide | J48: Africa | K48: 124937259 | L48: FALSE | M48: FALSE | N48: TRUE | O48: FALSE | P48: FALSE | Q48: FALSE | R48: FALSE | S48: FALSE | T48: TRUE | V48: Y | Y48: Y
A49: ET | B49: 44966 | D49: 7800 | E49: TRUE | F49: FALSE | G49: FALSE | H49: FALSE | I49: Nationwide | J49: Africa | K49: 124937259 | L49: TRUE | M49: FALSE | N49: FALSE | O49: FALSE | P49: TRUE | Q49: FALSE | R49: TRUE | S49: FALSE | T49: TRUE | V49: Y | Y49: Y
A50: ET | B50: 44139 | D50: 27648 | E50: FALSE | F50: FALSE | G50: TRUE | H50: FALSE | I50: Tigray region | J50: Africa | K50: 5443000 | L50: FALSE | M50: FALSE | N50: FALSE | O50: FALSE | P50: FALSE | Q50: FALSE | R50: FALSE | S50: FALSE | T50: FALSE | X50: Y
A51: GA | B51: 45164 | C51: 45168 | D51: 96 | E51: FALSE | F51: TRUE | G51: FALSE | H51: FALSE | I51: Nationwide | J51: Africa | K51: 2412778 | L51: FALSE | M51: FALSE | N51: FALSE | O51: FALSE | P51: FALSE | Q51: FALSE | R51: FALSE | S51: FALSE | T51: FALSE | U51: Y | Y51: Y
A52: GN | B52: 45254 | D52: 888 | E52: FALSE | F52: FALSE | G52: TRUE | H52: FALSE | I52: Nationwide | J52: Africa | K52: 14023588 | L52: TRUE | M52: FALSE | N52: FALSE | O52: FALSE | P52: TRUE | Q52: TRUE | R52: FALSE | S52: FALSE | T52: TRUE | V52: Y | Y52: Y
A53: GN | B53: 45063 | D53: 5472 | E53: TRUE | F53: FALSE | G53: FALSE | H53: FALSE | I53: Nationwide | J53: Africa | K53: 14023588 | L53: TRUE | M53: FALSE | N53: TRUE | O53: TRUE | P53: TRUE | Q53: TRUE | R53: TRUE | S53: TRUE | T53: TRUE | V53: Y | Y53: Y
A54: MR | B54: 45077 | C54: 45084 | D54: 168 | E54: TRUE | F54: FALSE | G54: FALSE | H54: FALSE | I54: Nationwide | J54: Africa | K54: 4798604 | L54: FALSE | M54: FALSE | N54: FALSE | O54: FALSE | P54: FALSE | Q54: FALSE | R54: FALSE | S54: FALSE | T54: FALSE | U54: Y | Y54: Y
A55: MR | B55: 44991 | C55: 44997 | D55: 144 | E55: TRUE | F55: FALSE | G55: FALSE | H55: FALSE | I55: Nationwide | J55: Africa | K55: 4798604 | L55: FALSE | M55: FALSE | N55: FALSE | O55: FALSE | P55: FALSE | Q55: FALSE | R55: FALSE | S55: FALSE | T55: FALSE | U55: Y | Y55: Y
A56: SN | B56: 45140 | D56: 3624 | E56: FALSE | F56: FALSE | G56: TRUE | H56: FALSE | I56: Nationwide | J56: Africa | K56: 17536231 | L56: FALSE | M56: FALSE | N56: FALSE | O56: FALSE | P56: FALSE | Q56: FALSE | R56: TRUE | S56: FALSE | T56: TRUE | V56: Y | Y56: Y
A57: SN | B57: 45138 | C57: 45145 | D57: 144 | E57: FALSE | F57: FALSE | G57: TRUE | H57: FALSE | I57: Nationwide | J57: Africa | K57: 17536231 | L57: FALSE | M57: FALSE | N57: FALSE | O57: FALSE | P57: FALSE | Q57: FALSE | R57: FALSE | S57: FALSE | T57: FALSE | U57: Y | Y57: Y
A58: SN | B58: 45081 | C58: 45084 | D58: 84 | E58: TRUE | F58: FALSE | G58: FALSE | H58: FALSE | I58: Nationwide | J58: Africa | K58: 17536231 | L58: FALSE | M58: FALSE | N58: FALSE | O58: FALSE | P58: FALSE | Q58: FALSE | R58: FALSE | S58: FALSE | T58: FALSE | U58: Y | Y58: Y
A59: SN | B59: 45078 | C59: 45144 | D59: 1584 | E59: TRUE | F59: FALSE | G59: FALSE | H59: FALSE | I59: Nationwide | J59: Africa | K59: 17536231 | L59: FALSE | M59: FALSE | N59: FALSE | O59: FALSE | P59: TRUE | Q59: FALSE | R59: FALSE | S59: FALSE | T59: TRUE | U59: Y | Y59: Y
A60: SN | B60: 45078 | C60: 45084 | D60: 180 | E60: TRUE | F60: FALSE | G60: FALSE | H60: FALSE | I60: Nationwide | J60: Africa | K60: 17536231 | L60: TRUE | M60: TRUE | N60: TRUE | O60: TRUE | P60: FALSE | Q60: TRUE | R60: FALSE | S60: FALSE | T60: TRUE | U60: Y | Y60: Y
A61: SO | B61: 45159 | D61: 3168 | E61: FALSE | F61: FALSE | G61: TRUE | H61: FALSE | I61: Nationwide | J61: Africa | K61: 17865030 | L61: FALSE | M61: FALSE | N61: FALSE | O61: FALSE | P61: TRUE | Q61: FALSE | R61: TRUE | S61: FALSE | T61: TRUE | V61: Y | Y61: Y
A62: SD | B62: 45031 | D62: 6240 | E62: FALSE | F62: FALSE | G62: TRUE | H62: FALSE | I62: Nationwide | J62: Africa | K62: 47486909 | L62: FALSE | M62: FALSE | N62: FALSE | O62: FALSE | P62: FALSE | Q62: FALSE | R62: FALSE | S62: FALSE | T62: FALSE | V62: Y | Y62: Y
A63: TZ | B63: 44972 | C63: 44973 | D63: 24 | E63: FALSE | F63: FALSE | G63: TRUE | H63: FALSE | I63: Nationwide | J63: Africa | K63: 66455898 | L63: FALSE | M63: FALSE | N63: FALSE | O63: FALSE | P63: FALSE | Q63: FALSE | R63: FALSE | S63: TRUE | T63: TRUE | U63: Y | Y63: Y
A64: ZW | B64: 45161 | C64: 45161 | D64: 8 | E64: FALSE | F64: TRUE | G64: FALSE | H64: FALSE | I64: Nationwide | J64: Africa | K64: 16488132 | L64: TRUE | M64: TRUE | N64: TRUE | O64: TRUE | P64: TRUE | Q64: FALSE | R64: FALSE | S64: FALSE | T64: TRUE | U64: Y | Y64: Y
A65: AZ | B65: 45188 | D65: 2472 | E65: FALSE | F65: FALSE | G65: TRUE | H65: FALSE | I65: Nagorno-Karabakh | J65: Asia | K65: 120000 | L65: FALSE | M65: FALSE | N65: FALSE | O65: FALSE | P65: FALSE | Q65: FALSE | R65: FALSE | S65: FALSE | T65: FALSE | V65: Y | Y65: Y
A66: CN | B66: 39995 | D66: 127104 | E66: FALSE | F66: FALSE | G66: TRUE | H66: FALSE | I66: Nationwide | J66: Asia | K66: 1425849288 | L66: TRUE | M66: TRUE | N66: TRUE | O66: FALSE | P66: FALSE | Q66: FALSE | R66: FALSE | S66: FALSE | T66: TRUE | X66: Y
A67: CN | B67: 42642 | D67: 63576 | E67: TRUE | F67: FALSE | G67: FALSE | H67: FALSE | I67: Nationwide | J67: Asia | K67: 1425849288 | L67: FALSE | M67: FALSE | N67: FALSE | O67: TRUE | P67: FALSE | Q67: FALSE | R67: FALSE | S67: FALSE | T67: TRUE | X67: Y
...

Sheet 2023H1 vs. 2022H1
A1: Summary of 2023'H1 and 2022'H1
B2: Countries restricting the internet in 2023'H1 | C2: Newly imposed restrictions in 2023'H1 Internet disruptions | D2: Affected people (if there were fer restrictions imposed in a country, biggest population sample is used); Data from UN, World Population Prospects 2022 | E2: Related w/ protests | F2: Related w/ elections | G2: Related w/ political turmoil | H2: Related w/ country’s internet law | I2: Soc media | J2: Local internet | K2: Nationwide internet | L2: Registered cases since 2015 | M2: Currently blocking | N2: Region
A3: BF | B3: Burkina Faso | C3: 0 | D3: 22959516 | E3: 0 | F3: 0 | G3: 0 | H3: 0 | I3: 0 | J3: 0 | K3: 0 | L3: 4 | M3: 1 | N3: Africa
A4: ER | B4: Eritrea | C4: 0 | D4: 3715522 | E4: 0 | F4: 0 | G4: 0 | H4: 0 | I4: 0 | J4: 0 | K4: 0 | L4: 2 | M4: 1 | N4: Africa
A5: ET | B5: Ethiopia | C5: 2 | D5: 124937259 | E5: 2 | F5: 0 | G5: 0 | H5: 0 | I5: 2 | J5: 0 | K5: 0 | L5: 12 | M5: 3 | N5: Africa
A6: GN | B6: Guinea | C6: 1 | D6: 14023588 | E6: 1 | F6: 0 | G6: 0 | H6: 0 | I6: 1 | J6: 0 | K6: 0 | L6: 4 | M6: 1 | N6: Africa
A7: MR | B7: Mauritania | C7: 2 | D7: 4798604 | E7: 2 | F7: 0 | G7: 0 | H7: 0 | I7: 0 | J7: 0 | K7: 2 | L7: 3 | M7: 0 | N7: Africa
A8: SN | B8: Senegal | C8: 2 | D8: 17536231 | E8: 0 | F8: 0 | G8: 2 | H8: 0 | I8: 1 | J8: 0 | K8: 1 | L8: 3 | M8: 0 | N8: Africa
A9: SD | B9: Sudan | C9: 1 | D9: 47486909 | E9: 0 | F9: 0 | G9: 1 | H9: 0 | I9: 0 | J9: 0 | K9: 1 | L9: 12 | M9: 1 | N9: Africa
A10: TZ | B10: Tanzania | C10: 1 | D10: 66455898 | E10: 0 | F10: 0 | G10: 1 | H10: 0 | I10: 1 | J10: 0 | K10: 0 | L10: 2 | M10: 0 | N10: Africa
A11: CN | B11: China | C11: 0 | D11: 1425849288 | E11: 0 | F11: 0 | G11: 0 | H11: 0 | I11: 0 | J11: 0 | K11: 0 | L11: 4 | M11: 4 | N11: Asia
A12: KP | B12: North Korea | C12: 0 | D12: 26116716 | E12: 0 | F12: 0 | G12: 0 | H12: 0 | I12: 0 | J12: 0 | K12: 0 | L12: 3 | M12: 3 | N12: Asia
A13: IN | B13: India | C13: 9 | D13: 1422026528 | E13: 7 | F13: 0 | G13: 2 | H13: 0 | I13: 1 | J13: 8 | K13: 0 | L13: 111 | M13: 3 | N13: Asia
A14: IR | B14: Iran | C14: 14 | D14: 88844498 | E14: 14 | F14: 0 | G14: 0 | H14: 0 | I14: 0 | J14: 14 | K14: 0 | L14: 41 | M14: 5 | N14: Asia
... A31: J&K | B31: Jammu and Kashmir | C31: 2 | D31: 13606320 | E31: 0 | F31: 0 | G31: 2 | H31: 0 | I31: 0 | J31: 2 | K31: 0 | L31: 326 | M31: 0 | N31: Asia
A34: 2022'H1
B35: Countries restricting the internet in 2022'H1 | C35: Newly imposed restrictions in 2022'H1 Internet disruptions | D35: Affected people (if there were fer restrictions imposed in a country, biggest population sample is used); Data from UN, World Population Prospects 2022 | E35: Related w/ protests | F35: Related w/ elections | G35: Related w/ political turmoil | H35: Related w/ country’s internet law | I35: Soc media | J35: Local internet | K35: Nationwide internet | L35: Registered cases since 2015 | M35: Currently blocking | N35: Region
A36: BF | B36: Burkina Faso | C36: 3 | D36: 22959516 | E36: 0 | F36: 0 | G36: 3 | H36: 0 | I36: 1 | J36: 0 | K36: 2 | L36: 4 | M36: 1 | N36: Africa
A37: ER | B37: Eritrea | C37: 0 | D37: 3715522 | E37: 0 | F37: 0 | G37: 0 | H37: 0 | I37: 0 | J37: 0 | K37: 0 | L37: 2 | M37: 1 | N37: Africa
A38: ET | B38: Ethiopia | C38: 0 | D38: 5443000 | E38: 0 | F38: 0 | G38: 0 | H38: 0 | I38: 0 | J38: 0 | K38: 0 | L38: 12 | M38: 1 | N38: Africa
A39: NG | B39: Nigeria | C39: 0 | D39: 221153992 | E39: 0 | F39: 0 | G39: 0 | H39: 0 | I39: 0 | J39: 0 | K39: 0 | L39: 1 | M39: 0 | N39: Africa
A40: SD | B40: Sudan | C40: 3 | D40: 47486909 | E40: 3 | F40: 0 | G40: 0 | H40: 0 | I40: 0 | J40: 0 | K40: 3 | L40: 12 | M40: 0 | N40: Africa
A41: ZW | B41: Zimbabwe | C41: 3 | D41: 16488132 | E41: 3 | F41: 0 | G41: 0 | H41: 0 | I41: 0 | J41: 0 | K41: 3 | L41: 6 | M41: 0 | N41: Africa
A42: CN | B42: China | C42: 0 | D42: 1425849288 | E42: 0 | F42: 0 | G42: 0 | H42: 0 | I42: 0 | J42: 0 | K42: 0 | L42: 4 | M42: 4 | N42: Asia
A43: KP | B43: North Korea | C43: 0 | D43: 26116716 | E43: 0 | F43: 0 | G43: 0 | H43: 0 | I43: 0 | J43: 0 | K43: 0 | L43: 3 | M43: 3 | N43: Asia
A44: IN | B44: India | C44: 6 | D44: 1422026528 | E44: 6 | F44: 0 | G44: 0 | H44: 0 | I44: 0 | J44: 6 | K44: 0 | L44: 111 | M44: 1 | N44: Asia
A45: IR | B45: Iran | C45: 1 | D45: 88844498 | E45: 1 | F45: 0 | G45: 0 | H45: 0 | I45: 0 | J45: 0 | K45: 1 | L45: 41 | M45: 3 | N45: Asia
A46: JO | B46: Jordan | C46: 1 | D46: 11315547 | E46: 0 | F46: 0 | G46: 1 | H46: 0 | I46: 1 | J46: 0 | K46: 0 | L46: 5 | M46: 0 | N46: Asia
A47: KZ | B47: Kazakhstan | C47: 1 | D47: 19500494 | E47: 1 | F47: 0 | G47: 0 | H47: 0 | I47: 0 | J47: 0 | K47: 1 | L47: 8 | M47: 0 | N47: Asia
... A61: J&K | B61: Jammu and Kashmir | C61: 35 | D61: 13606320 | E61: 1 | F61: 0 | G61: 34 | H61: 0 | I61: 0 | J61: 35 | K61: 0 | L61: 326 | M61: 0 | N61: Asia

Sheet 2022
A1: Summary of 2022. Below the summary, there is a list of all the 2022 cases
B2: Countries restricting the internet in 2022 | C2: Newly imposed restrictions in 2022 Internet disruptions | D2: Affected people (if there were fer restrictions imposed in a country, biggest population sample is used); Data from UN, World Population Prospects 2021 | E2: Related w/ protests | F2: Related w/ elections | G2: Related w/ political turmoil | H2: Related w/ country’s internet law | I2: Soc media | J2: Local internet | K2: Nationwide internet | L2: Registered cases since 2015 | M2: Currently blocking | N2: Region
A3: BF | B3: Burkina Faso | C3: 3 | D3: 20903273 | E3: 0 | F3: 0 | G3: 3 | H3: 0 | I3: 1 | J3: 0 | K3: 2 | L3: 4 | M3: Y | N3: Africa
A4: ER | B4: Eritrea | C4: 0 | D4: 3546421 | E4: 0 | F4: 0 | G4: 0 | H4: 0 | I4: 0 | J4: 0 | K4: 0 | L4: 2 | M4: Y | N4: Africa
A5: ET | B5: Ethiopia | C5: 0 | D5: 5443000 | E5: 0 | F5: 0 | G5: 0 | H5: 0 | I5: 0 | J5: 0 | K5: 0 | L5: 10 | M5: Y | N5: Africa
A6: NG | B6: Nigeria | C6: 0 | D6: 206139589 | E6: 0 | F6: 0 | G6: 0 | H6: 0 | I6: 0 | J6: 0 | K6: 0 | L6: 1 | N6: Africa
A7: SL | B7: Sierra Leone | C7: 2 | D7: 7976983 | E7: 2 | F7: 0 | G7: 0 | H7: 0 | I7: 0 | J7: 0 | K7: 2 | L7: 3 | N7: Africa
A8: SO | B8: Somalia | C8: 1 | D8: 477876 | E8: 1 | F8: 0 | G8: 0 | H8: 0 | I8: 0 | J8: 1 | K8: 0 | L8: 3 | N8: Africa
A9: SD | B9: Sudan | C9: 4 | D9: 43849260 | E9: 4 | F9: 0 | G9: 0 | H9: 0 | I9: 0 | J9: 0 | K9: 4 | L9: 11 | N9: Africa
A10: ZW | B10: Zimbabwe | C10: 3 | D10: 14862924 | E10: 3 | F10: 0 | G10: 0 | H10: 0 | I10: 0 | J10: 0 | K10: 3 | L10: 6 | N10: Africa
A11: AF | B11: Afghanistan | C11: 1 | D11: 38928346 | E11: 0 | F11: 0 | G11: 1 | H11: 0 | I11: 0 | J11: 0 | K11: 1 | L11: 2 | N11: Asia
A12: AM | B12: Armenia | C12: 1 | D12: 2963243 | E12: 0 | F12: 0 | G12: 1 | H12: 0 | I12: 1 | J12: 0 | K12: 0 | L12: 3 | N12: Asia
A13: AZ | B13: Azerbaijan | C13: 1 | D13: 10139177 | E13: 0 | F13: 0 | G13: 1 | H13: 0 | I13: 1 | J13: 0 | K13: 0 | L13: 2 | M13: Y | N13: Asia
A14: CN | B14: China | C14: 0 | D14: 1439323776 | E14: 0 | F14: 0 | G14: 0 | H14: 0 | I14: 0 | J14: 0 | K14: 0 | L14: 4 | M14: Y | N14: Asia
A15: KP | B15: North Korea | C15: 0 | D15: 25778816 | E15: 0 | F15: 0 | G15: 0 | H15: 0 | I15: 0 | J15: 0 | K15: 0 | L15: 3 | M15: Y | N15: Asia
A16: IN | B16: India | C16: 10 | D16: 1380004385 | E16: 9 | F16: 0 | G16: 1 | H16: 0 | I16: 0 | J16: 10 | K16: 0 | L16: 102 | M16: Y | N16: Asia
A17: IR | B17: Iran | C17: 11 | D17: 83992949 | E17: 10 | F17: 0 | G17: 1 | H17: 0 | I17: 2 | J17: 4 | K17: 5 | L17: 27 | M17: Y | N17: Asia
A18: JO | B18: Jordan | C18: 2 | D18: 10203134 | E18: 1 | F18: 0 | G18: 1 | H18: 0 | I18: 2 | J18: 0 | K18: 0 | L18: 5 | M18: Y | N18: Asia
A19: KZ | B19: Kazakhstan | C19: 2 | D19: 18776707 | E19: 2 | F19: 0 | G19: 0 | H19: 0 | I19: 0 | J19: 1 | K19: 1 | L19: 8 | N19: Asia
A20: MM | B20: Myanmar | C20: 0 | D20: 54409800 | E20: 0 | F20: 0 | G20: 0 | H20: 0 | I20: 0 | J20: 0 | K20: 0 | L20: 6 | M20: Y | N20: Asia
A21: OM | B21: Oman | C21: 0 | D21: 5106626 | E21: 0 | F21: 0 | G21: 0 | H21: 0 | I21: 0 | J21: 0 | K21: 0 | L21: 3 | M21: Y | N21: Asia
A22: PK | B22: Pakistan | C22: 3 | D22: 220892340 | E22: 1 | F22: 0 | G22: 2 | H22: 0 | I22: 2 | J22: 1 | K22: 0 | L22: 12 | N22: Asia
A23: QA | B23: Qatar | C23: 0 | D23: 2881053 | E23: 0 | F23: 0 | G23: 0 | H23: 0 | I23: 0 | J23: 0 | K23: 0 | L23: 1 | M23: Y | N23: Asia
A24: LK | B24: Sri Lanka | C24: 2 | D24: 21413249 | E24: 2 | F24: 0 | G24: 0 | H24: 0 | I24: 1 | J24: 0 | K24: 1 | L24: 5 | N24: Asia
A25: TH | B25: Thailand | C25: 0 | D25: 69799978 | E25: 0 | F25: 0 | G25: 0 | H25: 0 | I25: 0 | J25: 0 | K25: 0 | L25: 1 | M25: Y | N25: Asia
A26: TM | B26: Turkmenistan | C26: 0 | D26: 6031200 | E26: 0 | F26: 0 | G26: 0 | H26: 0 | I26: 0 | J26: 0 | K26: 0 | L26: 4 | M26: Y | N26: Asia
A27: AE | B27: U.A.E. | C27: 0 | D27: 9890402 | E27: 0 | F27: 0 | G27: 0 | H27: 0 | I27: 0 | J27: 0 | K27: 0 | L27: 2 | M27: Y | N27: Asia
A28: UZ | B28: Uzbekistan | C28: 1 | D28: 33469203 | E28: 1 | F28: 0 | G28: 0 | H28: 0 | I28: 0 | J28: 0 | K28: 1 | L28: 6 | M28: Y | N28: Asia
A29: YE | B29: Yemen | C29: 0 | D29: 29825964 | E29: 0 | F29: 0 | G29: 0 | H29: 0 | I29: 0 | J29: 0 | K29: 0 | L29: 3 | M29: Y | N29: Asia
A30: RU | B30: Russia | C30: 3 | D30: 145934462 | E30: 0 | F30: 0 | G30: 3 | H30: 0 | I30: 3 | J30: 0 | K30: 0 | L30: 9 | M30: Y | N30: Europe
A31: UA | B31: Ukraine | C31: 0 | D31: 43733762 | E31: 0 | F31: 0 | G31: 0 | H31: 0 | I31: 0 | J31: 0 | K31: 0 | L31: 1 | M31: Y | N31: Europe
A32: CU | B32: Cuba | C32: 3 | D32: 11326616 | E32: 3 | F32: 0 | G32: 0 | H32: 0 | I32: 0 | J32: 0 | K32: 3 | L32: 7 | N32: North America
A33: BR | B33: Brazil | C33: 1 | D33: 212559417 | E33: 0 | F33: 0 | G33: 1 | H33: 0 | I33: 1 | J33: 0 | K33: 0 | L33: 4 | N33: South America
A34: J&K | B34: Jammu and Kashmir | C34: 24 | D34: 13606320 | E34: 0 | F34: 0 | G34: 24 | H34: 0 | I34: 0 | J34: 24 | K34: 0 | L34: 306 | N34: Asia
A40: List of all restrictions in 2022
A41: Iso-2 array | B41: Start date | C41: End date | D41: Duration (until the end of 2022), h | E41: If yes, what was the context? | F41: Related w/ protests | G41: Related w/ elections | H41: Related w/ political turmoil | I41: Related w/ country’s internet law | J41: Scope/population? | K41: Region | L41: Population; Data from UN, World Population Prospects 2021 | M41: Facebook | N41: Twitter | O41: Youtube | P41: Instagram | Q41: Telegram | R41: Whatsapp | S41: Other soc. media | T41: Other VoIP apps | U41: Service based restriction | V41: Cases that started and ended in chosen period | W41: Cases that started in chosen period and are still ongoing | X41: Cases that started earlier but ended in chosen period | Y41: Cases that started earlier and are still ongoing | Z41: Cases that started in this period
A42: BF | B42: 44584 | C42: 44585 | D42: 35 | E42: Internet disrupted in Burkina Faso amid military uprising | F42: FALSE | G42: FALSE | H42: TRUE | I42: FALSE | J42: Nationwide | K42: Africa | L42: 20903273 | M42: FALSE | N42: FALSE | O42: FALSE | P42: FALSE | Q42: FALSE | R42: FALSE | S42: FALSE | T42: FALSE | U42: FALSE | V42: Y | Z42: Y
A43: BF | B43: 44572 | D43: 8496 | E43: On 19 January 2022, authorities admitted that they restricted access to Facebook services citing security concern. Restrictions started on 11 January. | F43: FALSE | G43: FALSE | H43: TRUE | I43: FALSE | J43: Nationwide | K43: Africa | L43: 20903273 | M43: TRUE | N43: FALSE | O43: FALSE | P43: FALSE | Q43: FALSE | R43: FALSE | S43: FALSE | T43: FALSE | U43: TRUE | W43: Y | Z43: Y
A44: BF | B44: 44571 | C44: 44572 | D44: 15 | E44: Internet disruptions observed in Burkina Faso amid coup plot arrests. | F44: FALSE | G44: FALSE | H44: TRUE | I44: FALSE | J44: Nationwide | K44: Africa | L44: 20903273 | M44: FALSE | N44: FALSE | O44: FALSE | P44: FALSE | Q44: FALSE | R44: FALSE | S44: FALSE | T44: FALSE | U44: FALSE | V44: Y | Z44: Y
A45: ER | B45: 40544 | D45: 105168 | E45: According to Freedom House, Eritrea has one of the worst infrastructures in Africa, it is possible that some ISPs deliberately block services, but the government’s poor human rights record indicates that the inaccessibility of YouTube could be related to censorship. | F45: FALSE | G45: FALSE | H45: TRUE | I45: FALSE | J45: Nationwide | K45: Africa | L45: 3546421 | M45: FALSE | N45: FALSE | O45: TRUE | P45: FALSE | Q45: FALSE | R45: FALSE | S45: FALSE | T45: FALSE | U45: TRUE | Y45: Y
...

Sheet 2021
A1: Summary of 2021. Below the summary, there is a list of all the 2021 cases
B2: Countries restricting the internet in 2021 | C2: Newly imposed restrictions in 2021 Internet disruptions | D2: Affected people (if there were fer restrictions imposed in a country, biggest population sample is used); Data from UN, World Population Prospects 2021 | E2: Related w/ protests | F2: Related w/ elections | G2: Related w/ political turmoil | H2: Related w/ country’s internet law | I2: Soc media | J2: Local internet | K2: Nationwide internet | L2: Registered cases since 2015 | M2: Currently blocking | N2: Region
A3: BF | B3: Burkina Faso | C3: 1 | D3: 20903273 | E3: 1 | F3: 0 | G3: 0 | H3: 0 | I3: 0 | J3: 0 | K3: 1 | L3: 4 | N3: Africa
A4: TD | B4: Chad | C4: 1 | D4: 16425864 | E4: 0 | F4: 0 | G4: 1 | H4: 0 | I4: 0 | J4: 0 | K4: 1 | L4: 5 | N4: Africa
A5: CG | B5: Congo | C5: 1 | D5: 5518087 | E5: 0 | F5: 1 | G5: 0 | H5: 0 | I5: 0 | J5: 0 | K5: 1 | L5: 3 | N5: Africa
A6: ER | B6: Eritrea | C6: 0 | D6: 3546421 | E6: 0 | F6: 0 | G6: 0 | H6: 0 | I6: 0 | J6: 0 | K6: 0 | L6: 2 | M6: Y | N6: Africa
A7: SZ | B7: Eswatini | C7: 2 | D7: 1160164 | E7: 2 | F7: 0 | G7: 0 | H7: 0 | I7: 1 | J7: 0 | K7: 1 | L7: 2 | N7: Africa
A8: ET | B8: Ethiopia | C8: 0 | D8: 5443000 | E8: 0 | F8: 0 | G8: 0 | H8: 0 | I8: 0 | J8: 0 | K8: 0 | L8: 10 | M8: Y | N8: Africa
A9: NE | B9: Niger | C9: 1 | D9: 24206644 | E9: 1 | F9: 0 | G9: 0 | H9: 0 | I9: 0 | J9: 0 | K9: 1 | L9: 2 | N9: Africa
A10: NG | B10: Nigeria | C10: 1 | D10: 206139589 | E10: 0 | F10: 0 | G10: 1 | H10: 0 | I10: 1 | J10: 0 | K10: 0 | L10: 1 | M10: Y | N10: Africa
A11: SS | B11: South Sudan | C11: 1 | D11: 11193725 | E11: 1 | F11: 0 | G11: 0 | H11: 0 | I11: 0 | J11: 0 | K11: 1 | L11: 1 | N11: Africa
A12: SN | B12: Senegal | C12: 1 | D12: 16743927 | E12: 1 | F12: 0 | G12: 0 | H12: 0 | I12: 1 | J12: 0 | K12: 0 | L12: 1 | N12: Africa
A13: SD | B13: Sudan | C13: 4 | D13: 43849260 | E13: 2 | F13: 0 | G13: 2 | H13: 0 | I13: 1 | J13: 0 | K13: 3 | L13: 11 | N13: Africa
A14: UG | B14: Uganda | C14: 3 | D14: 45741007 | E14: 0 | F14: 3 | G14: 0 | H14: 0 | I14: 2 | J14: 0 | K14: 1 | L14: 5 | N14: Africa
A15: ZM | B15: Zambia | C15: 1 | D15: 18383955 | E15: 0 | F15: 1 | G15: 0 | H15: 0 | I15: 1 | J15: 0 | K15: 0 | L15: 1 | N15: Africa
